<robot name="car">
  <material name="white">
    <color rgba="1.0 1.0 1.0 1.0"/>
  </material>
  <link name="world"/>
  <joint name="fixed" type="fixed">
    <origin rpy="0 0 0" xyz="0 0 0.115"/>
    <parent link="world"/>
    <child link="baseplate"/>
  </joint>
  <link name="baseplate">
    <visual>
      <geometry>
        <mesh filename="package://car_description/meshes/baseplate.STL"/>
      </geometry>
      <origin rpy="0 0 0" xyz="0 0 0"/>
      <material name="white"/>
    </visual>
    <collision>
      <geometry>
        <mesh filename="package://car_description/meshes/baseplate.STL"/>
      </geometry>
      <origin rpy="0 0 0" xyz="0 0 0"/>
    </collision>
    <inertial>
      <mass value="3.0"/>
      <origin rpy="0 0 0" xyz="0.08 0 -0.03"/>
      <inertia ixx="0.0291" ixy="0" ixz="0" iyy="0.029925" iyz="0" izz="0.056325"/>
    </inertial>
  </link>
  <gazebo reference="baseplate">
    <material>Gazebo/Red</material>
  </gazebo>
  <joint name="joint1" type="continuous">
    <origin rpy="0 0 0" xyz="0 -0.15 -0.04"/>
    <axis xyz="0 1 0"/>
    <parent link="baseplate"/>
    <child link="wheel1"/>
    <dynamics damping="0.1"/>
    <!--<limit effort="100" lower="-3.1415" upper="3.1415" velocity="3.0" />-->
  </joint>
  <transmission name="joint1_trans">
    <type>transmission_interface/SimpleTransmission</type>
    <joint name="joint1">
      <hardwareInterface>hardware_interface/EffortJointInterface</hardwareInterface>
    </joint>
    <actuator name="joint1_motor">
      <hardwareInterface>hardware_interface/EffortJointInterface</hardwareInterface>
      <mechanismReduction>1</mechanismReduction>
    </actuator>
  </transmission>
  <link name="wheel1">
    <visual>
      <geometry>
        <mesh filename="package://car_description/meshes/wheel1.STL"/>
      </geometry>
      <origin rpy="0 0 0" xyz="0 0.15 0.04"/>
      <material name="white"/>
    </visual>
    <collision>
      <geometry>
        <mesh filename="package://car_description/meshes/wheel1.STL"/>
      </geometry>
      <origin rpy="0 0 0" xyz="0 0.15 0.04"/>
    </collision>
    <inertial>
      <mass value="0.4"/>
      <origin rpy="0 0 0" xyz="0 -0.015 0"/>
      <inertia ixx="0.000785" ixy="0" ixz="0" iyy="0.001491" iyz="0" izz="0.000785"/>
    </inertial>
  </link>
  <gazebo reference="wheel1">
    <material>Gazebo/Red</material>
  </gazebo>
  <joint name="joint2" type="continuous">
    <origin rpy="0 0 0" xyz="0 0.15 -0.04"/>
    <axis xyz="0 1 0"/>
    <parent link="baseplate"/>
    <child link="wheel2"/>
    <dynamics damping="0.1"/>
    <!--<limit effort="100" lower="-3.1415" upper="3.1415" velocity="3.0" />-->
  </joint>
  <transmission name="joint2_trans">
    <type>transmission_interface/SimpleTransmission</type>
    <joint name="joint2">
      <hardwareInterface>hardware_interface/EffortJointInterface</hardwareInterface>
    </joint>
    <actuator name="joint2_motor">
      <hardwareInterface>hardware_interface/EffortJointInterface</hardwareInterface>
      <mechanismReduction>1</mechanismReduction>
    </actuator>
  </transmission>
  <link name="wheel2">
    <visual>
      <geometry>
        <mesh filename="package://car_description/meshes/wheel2.STL"/>
      </geometry>
      <origin rpy="0 0 0" xyz="0 -0.15 0.04"/>
      <material name="white"/>
    </visual>
    <collision>
      <geometry>
        <mesh filename="package://car_description/meshes/wheel2.STL"/>
      </geometry>
      <origin rpy="0 0 0" xyz="0 -0.15 0.04"/>
    </collision>
    <inertial>
      <mass value="0.4"/>
      <origin rpy="0 0 0" xyz="0 0.015 0"/>
      <inertia ixx="0.000785" ixy="0" ixz="0" iyy="0.001491" iyz="0" izz="0.000785"/>
    </inertial>
  </link>
  <gazebo reference="wheel2">
    <material>Gazebo/Red</material>
  </gazebo>
  <joint name="joint3" type="continuous">
    <origin rpy="0 0 0" xyz="0.2225 0 -0.0875"/>
    <axis xyz="0 1 0"/>
    <parent link="baseplate"/>
    <child link="support"/>
    <dynamics damping="0.1"/>
    <!--<limit effort="100" lower="-3.1415" upper="3.1415" velocity="3.0" />-->
  </joint>
  <transmission name="joint3_trans">
    <type>transmission_interface/SimpleTransmission</type>
    <joint name="joint3">
      <hardwareInterface>hardware_interface/EffortJointInterface</hardwareInterface>
    </joint>
    <actuator name="joint3_motor">
      <hardwareInterface>hardware_interface/EffortJointInterface</hardwareInterface>
      <mechanismReduction>1</mechanismReduction>
    </actuator>
  </transmission>
  <link name="support">
    <visual>
      <geometry>
        <mesh filename="package://car_description/meshes/support.STL"/>
      </geometry>
      <origin rpy="0 0 0" xyz="-0.2225 0 0.0875"/>
      <material name="white"/>
    </visual>
    <collision>
      <geometry>
        <mesh filename="package://car_description/meshes/support.STL"/>
      </geometry>
      <origin rpy="0 0 0" xyz="-0.2225 0 0.0875"/>
    </collision>
    <inertial>
      <mass value="1.8"/>
      <origin rpy="0 0 0" xyz="0 0 0"/>
      <inertia ixx="0.000785" ixy="0" ixz="0" iyy="0.001491" iyz="0" izz="0.000785"/>
    </inertial>
  </link>
  <gazebo reference="support">
    <material>Gazebo/Red</material>
  </gazebo>
</robot>
