<?xml version="1.0"?>
<robot name="car" xmlns:xacro="http://ros.org/wiki/xacro">
  <xacro:property name="baseplate_wide" value="0.3" />
  <xacro:property name="axis_offset" value="0.04" />
  <xacro:property name="high_offset" value="0.115" />

  <material name="white">
    <color rgba="1.0 1.0 1.0 1.0"/>
  </material>

  <gazebo>
    <plugin name="gazebo_ros_control" filename="libgazebo_ros_control.so">
      <robotNamespace>/car</robotNamespace>
      <robotSimType>gazebo_ros_control/DefaultRobotHWSim</robotSimType>
      <legacyModeNS>true</legacyModeNS>
    </plugin>
  </gazebo>
<!--
  <link name="world"/>
  <joint name="fixed" type="fixed">
  <origin xyz="0 0 ${high_offset}" rpy="0 0 0"/>
    <parent link="world"/>
    <child link="baseplate"/>
  </joint>
-->

  <link name="baseplate">
    <visual>
      <geometry>
        <mesh filename="package://car_description/meshes/baseplate.STL" />
      </geometry>
      <origin xyz="0 0 0" rpy="0 0 0"/>
      <material name="white"/>
    </visual>
    <collision>
      <geometry>
        <mesh filename="package://car_description/meshes/baseplate.STL" />
      </geometry>
      <origin xyz="0 0 0" rpy="0 0 0"/>
    </collision>
    <inertial>
      <mass value="1.0"/>
      <origin xyz="0.08 0 -0.03" rpy="0 0 0"/>
      <inertia ixx="0.001" ixy="0.0" ixz="0.0" iyy="0.001" iyz="0.0" izz="0.001"/>
    </inertial>
  </link>
  <gazebo reference="baseplate">
    <material>Gazebo/Red</material>
  </gazebo>


  <joint name="joint1" type="continuous">
    <origin xyz="0 ${-baseplate_wide/2} ${-axis_offset}" rpy="0 0 0"/>
    <axis xyz="0 1 0"/>
    <parent link="baseplate"/>
    <child link="wheel1"/>
    <dynamics damping="0.1"/>
    <limit velocity="12.0" effort="0.4" />
  </joint>
  <transmission name="joint1_trans">
    <type>transmission_interface/SimpleTransmission</type>
    <joint name="joint1">
      <hardwareInterface>hardware_interface/VelocityJointInterface </hardwareInterface>
    </joint>
    <actuator name="joint1_motor">
       <hardwareInterface>hardware_interface/VelocityJointInterface </hardwareInterface>
       <mechanismReduction>1</mechanismReduction>
    </actuator>
  </transmission>

  <link name="wheel1">
    <visual>
      <geometry>
        <mesh filename="package://car_description/meshes/wheel1.STL" />
      </geometry>
      <origin xyz="0 ${baseplate_wide/2} ${axis_offset}" rpy="0 0 0"/>
      <material name="white"/>
    </visual>
    <collision>
      <geometry>
        <mesh filename="package://car_description/meshes/wheel1.STL" />
      </geometry>
      <origin xyz="0 ${baseplate_wide/2} ${axis_offset}" rpy="0 0 0"/>
    </collision>
    <inertial>
      <mass value="0.1"/>
      <origin xyz="0 -0.015 0" rpy="0 0 0"/>
      <inertia ixx="0.0001" ixy="0.0" ixz="0.0" iyy="0.0001" iyz="0.0" izz="0.0001"/>
    </inertial>
  </link>
  <gazebo reference="wheel1">
    <material>Gazebo/Red</material>
    <mu1 value="2.5" />
    <mu2 value="2.5" />
    <kp value="50000" />
    <kd value="10" />
  </gazebo>

  <joint name="joint2" type="continuous">
    <origin xyz="0 ${baseplate_wide/2} ${-axis_offset}" rpy="0 0 0"/>
    <axis xyz="0 1 0"/>
    <parent link="baseplate"/>
    <child link="wheel2"/>
    <dynamics damping="0.1"/>
    <limit velocity="12.0" effort="0.4" />
  </joint>
  <transmission name="joint2_trans">
    <type>transmission_interface/SimpleTransmission</type>
    <joint name="joint2">
      <hardwareInterface>hardware_interface/VelocityJointInterface </hardwareInterface>
    </joint>
    <actuator name="joint2_motor">
       <hardwareInterface>hardware_interface/VelocityJointInterface </hardwareInterface>
       <mechanismReduction>1</mechanismReduction>
    </actuator>
  </transmission>

  <link name="wheel2">
    <visual>
      <geometry>
        <mesh filename="package://car_description/meshes/wheel2.STL" />
      </geometry>
      <origin xyz="0 ${-baseplate_wide/2} ${axis_offset}" rpy="0 0 0"/>
      <material name="white"/>
    </visual>
    <collision>
      <geometry>
        <mesh filename="package://car_description/meshes/wheel2.STL" />
      </geometry>
      <origin xyz="0 ${-baseplate_wide/2} ${axis_offset}" rpy="0 0 0"/>
    </collision>
    <inertial>
      <mass value="0.1"/>
      <origin xyz="0 0.015 0" rpy="0 0 0"/>
      <inertia ixx="0.0001" ixy="0.0" ixz="0.0" iyy="0.0001" iyz="0.0" izz="0.0001"/>
    </inertial>
  </link>
  <gazebo reference="wheel2">
    <material>Gazebo/Red</material>
    <mu1 value="2.5" />
    <mu2 value="2.5" />
    <kp value="50000" />
    <kd value="10" />
  </gazebo>

  <joint name="joint3" type="continuous">
    <origin xyz="0.2225 0 -0.0875" rpy="0 0 0"/>
    <axis xyz="0 1 0"/>
    <parent link="baseplate"/>
    <child link="support"/>
    <dynamics damping="0.1"/>
    <limit velocity="12.0" effort="0.4" />
  </joint>
  <transmission name="joint3_trans">
    <type>transmission_interface/SimpleTransmission</type>
    <joint name="joint3">
      <hardwareInterface>hardware_interface/VelocityJointInterface </hardwareInterface>
    </joint>
    <actuator name="joint3_motor">
       <hardwareInterface>hardware_interface/VelocityJointInterface </hardwareInterface>
       <mechanismReduction>1</mechanismReduction>
    </actuator>
  </transmission>

  <link name="support">
    <visual>
      <geometry>
        <mesh filename="package://car_description/meshes/support.STL" />
      </geometry>
      <origin xyz="-0.2225 0 0.0875" rpy="0 0 0"/>
      <material name="white"/>
    </visual>
    <collision>
      <geometry>
        <mesh filename="package://car_description/meshes/support.STL" />
      </geometry>
      <origin xyz="-0.2225 0 0.0875" rpy="0 0 0"/>
    </collision>
    <inertial>
      <mass value="1.8"/>
      <origin xyz="0 0 0" rpy="0 0 0"/>
      <inertia ixx="0.000785" ixy="0" ixz="0" iyy="0.001491" iyz="0" izz="0.000785"/>
    </inertial>
  </link>
  <gazebo reference="support">
    <material>Gazebo/Red</material>
    <mu1 value="0.1" />
    <mu2 value="0.1" />
  </gazebo>
</robot>